Workbook

Sheet Guideline
A1: Guideline to make and understand Unit Test Case
A3: 1. Overview
A4: - In the template, Unit test cases are based on functions. Each sheet presents test cases for one function.
A5: - Cover: General information of the project and Unit Test cases
A6: - FunctionList: The list of Classes and Functions in the document. + To control that the number of Unit TC meets customer's requirement or the norm, user should fill value for 'Normal number of Test cases/KLOC'.
A7: + Click on Function link to open the related Test cases of the function. Note: You should create new Function sheet before creating the link
A8: - Test Report: provive the overview results of Functions Unit test: Test coverage, Test successful coverage (Summary, for normal/abnormal/boundary cases)
A9: Note: Should check the formula of "Sub Total" if you add more functions
A11: 2. Content in Test function sheet
A12: 2.1 Combination of test cases.
A13: - To verify that number of Unit TC meets customer's requirement or not. User has to fill number LOC of tested function and fill value of 'Normal number test cases/KLOC' item in FunctionList sheet, which is required by customer or normal value. The number of lacked TC is shown in 'Lack of test cases' item.
A14: - If the number of Unit TC does not meet the requirement, creator should explain the reasons.
... A47: - Test requirement: Brief description about requirements which are tested in this function, it is not mandatory.

Sheet Cover
B2: UNIT TEST DOCUMENT
A4: Project Name | B4: Develop an AI-Assisted Omnichannel Order Fulfillment and Packaging Optimization System (OptiPack AI) | E4: Creator | F4: Nguyễn Phương Mỹ Thuận
A5: Project Code | B5: FA26SE036 | E5: Issue Date | F5: 25/10/2026
A6: Document Code | B6: =B5&"_"&"Unit Test"&"_"&"v1.0" | E6: Version | F6: 1.0
A9: Record of change
A10: Effective Date | B10: Version | C10: Change Item | D10: *A,D,M | E10: Change description | F10: Reference
A11: 25/10/2026 | B11: 1.0 | C11: Whole document | D11: A | E11: Unit test cases of 5 core back-end functions, mapped to the Jest tests that run in CI on tag review-2 | F11: Report 3 (SRS), Report 4 (SDD), Report5_Test_Report.xlsx

Sheet Functions
E2: Function List
A4: Project Name | E4: =Cover!B4
A5: Project Code | E5: =Cover!B5
A6: Normal number of Test cases/KLOC | E6: 100
A7: Test Environment Setup Description | E7: 1. Node.js 22, Jest 30 + ts-jest (npm run test in be/) 2. MongoDB models mocked in unit tests (no database needed) 3. CI: GitHub Actions ubuntu-latest, job "Backend (typecheck, lint, test)"
A10: No | B10: Requirement Name | C10: Class Name | D10: Function Name | E10: Function Code(Optional) | F10: Sheet Name | G10: Description | H10: Pre-Condition
A11: 1 | B11: Staff login with e-mail / password, lockout, 72-hour tempora | C11: AuthService | D11: login | E11: UT-AUTH-LOGIN | F11: UT-AUTH-LOGIN | G11: Staff login with e-mail / password, lockout, 72-hour temporary password, optional two-factor (TOTP, backup code, trusted device) – SRS 3.2.1 | H11: Can connect to MongoDB (mocked model)
A12: 2 | B12: Scan one item while picking: SKU of the group, ordered quant | C12: OrderGroupsService | D12: pickItem | E12: UT-PICK-ITEM | F12: UT-PICK-ITEM | G12: Scan one item while picking: SKU of the group, ordered quantity, FIFO lot, idempotent scan – SRS 3.5.1 | H12: MongoDB transaction available (mocked)
A13: 3 | B13: Allowed Order Group status transitions (33) and rejection of | C13: allowed-status-transitions | D13: isValidStatusTransition / getAllowedNextStatuses | E13: UT-GROUP-TRANS | F13: UT-GROUP-TRANS | G13: Allowed Order Group status transitions (33) and rejection of invalid jumps – SDD 3.8 | H13: Pure function, no external dependency
A14: 4 | B14: Return ticket rules: 15-day window, one open ticket, no self | C14: ReturnsService | D14: createSimulated / approve / reject / receive / inspect | E14: UT-RETURNS | F14: UT-RETURNS | G14: Return ticket rules: 15-day window, one open ticket, no self-approval, reason required, inspection – SRS 3.8, BR-11, BR-12 | H14: MongoDB transaction available (mocked)
A15: 5 | B15: 3D packing plan per order: valid placement, determinism, fra | C15: solve-order (BRKGA + EMS) | D15: solveOrder | E15: UT-SOLVER | F15: UT-SOLVER | G15: 3D packing plan per order: valid placement, determinism, fragile items, folding, box stock and exclusions – SRS 3.6.1, BR-06, BR-15 | H15: Box catalog with stock (fixture)

Sheet Statistics
A2: UNIT TEST REPORT
A4: Project Name | B4: =Cover!B4 | D4: Creator | F4: Nguyễn Phương Mỹ Thuận
A5: Project Code | B5: =Cover!B5 | D5: Reviewer/Approver | F5: Thân Thị Ngọc Vân
A6: Document Code | B6: =B5&"_"&"Unit Test Report"&"_"&"v1.0" | D6: Issue Date | F6: 25/10/2026
A7: Notes | B7: Review 2 release (tag review-2): unit tests of 5 core back-end functions; all cases run automatically in CI (Jest).
A11: No | B11: Function code | C11: Passed | D11: Failed | E11: Untested | F11: N | G11: A | H11: B | I11: Total Test Cases
A12: 1 | B12: UT-AUTH-LOGIN | C12: ='UT-AUTH-LOGIN'!A7 | D12: ='UT-AUTH-LOGIN'!C7 | E12: ='UT-AUTH-LOGIN'!F7 | F12: ='UT-AUTH-LOGIN'!L7 | G12: ='UT-AUTH-LOGIN'!M7 | H12: ='UT-AUTH-LOGIN'!N7 | I12: ='UT-AUTH-LOGIN'!O7
A13: 2 | B13: UT-PICK-ITEM | C13: ='UT-PICK-ITEM'!A7 | D13: ='UT-PICK-ITEM'!C7 | E13: ='UT-PICK-ITEM'!F7 | F13: ='UT-PICK-ITEM'!L7 | G13: ='UT-PICK-ITEM'!M7 | H13: ='UT-PICK-ITEM'!N7 | I13: ='UT-PICK-ITEM'!O7
A14: 3 | B14: UT-GROUP-TRANS | C14: ='UT-GROUP-TRANS'!A7 | D14: ='UT-GROUP-TRANS'!C7 | E14: ='UT-GROUP-TRANS'!F7 | F14: ='UT-GROUP-TRANS'!L7 | G14: ='UT-GROUP-TRANS'!M7 | H14: ='UT-GROUP-TRANS'!N7 | I14: ='UT-GROUP-TRANS'!O7
A15: 4 | B15: UT-RETURNS | C15: ='UT-RETURNS'!A7 | D15: ='UT-RETURNS'!C7 | E15: ='UT-RETURNS'!F7 | F15: ='UT-RETURNS'!L7 | G15: ='UT-RETURNS'!M7 | H15: ='UT-RETURNS'!N7 | I15: ='UT-RETURNS'!O7
A16: 5 | B16: UT-SOLVER | C16: ='UT-SOLVER'!A7 | D16: ='UT-SOLVER'!C7 | E16: ='UT-SOLVER'!F7 | F16: ='UT-SOLVER'!L7 | G16: ='UT-SOLVER'!M7 | H16: ='UT-SOLVER'!N7 | I16: ='UT-SOLVER'!O7
B17: Sub total | C17: =SUM(C12:C16) | D17: =SUM(D12:D16) | E17: =SUM(E12:E16) | F17: =SUM(F12:F16) | G17: =SUM(G12:G16) | H17: =SUM(H12:H16) | I17: =SUM(I12:I16)
B19: Test coverage | D19: =(C17+D17)*100/(I17) | E19: %
B20: Test successful coverage | D20: =C17*100/(I17) | E20: %
B21: Normal case | D21: =F17*100/I17 | E21: %
B22: Abnormal case | D22: =G17*100/I17 | E22: %
B23: Boundary case | D23: =H17*100/I17 | E23: %

Sheet UT-AUTH-LOGIN
A2: Function Code | C2: UT-AUTH-LOGIN | F2: Function Name | L2: AuthService.login
A3: Created By | C3: Thuận | F3: Executed By | L3: GitHub Actions CI (run #258, commit 1a3101c)
A4: Lines of code | C4: 143 | F4: Lack of test cases | L4: =IF(Functions!E6<>"N/A",SUM(C4*Functions!E6/1000,-O7),"N/A")
A5: Test requirement | C5: Staff login with e-mail / password, lockout, 72-hour temporary password, optional two-factor (TOTP, backup code, trusted device) – SRS 3.2.1. Test file: be/src/modules/auth/auth.service.spec.ts; source: be/src/modules/auth/auth.service.ts
A6: Passed | C6: Failed | F6: Untested | L6: N/A/B | O6: Total Test Cases
A7: =COUNTIF(F42:R42,"P") | C7: =COUNTIF(F42:R42,"F") | F7: =SUM(O7,-A7,-C7) | L7: =COUNTIF(F41:R41,"N") | M7: =COUNTIF(F41:R41,"A") | N7: =COUNTIF(F41:R41,"B") | O7: =COUNTA(F9:R9)
F9: UTCID01 | G9: UTCID02 | H9: UTCID03 | I9: UTCID04 | J9: UTCID05 | K9: UTCID06 | L9: UTCID07 | M9: UTCID08 | N9: UTCID09 | O9: UTCID10 | P9: UTCID11 | Q9: UTCID12 | R9: UTCID13
A10: Condition | B10: Precondition
D11: Can connect to MongoDB (mocked model) | F11: O | G11: O | H11: O | I11: O | J11: O | K11: O | L11: O | M11: O | N11: O | O11: O | P11: O | Q11: O | R11: O
B12: User
D13: exists, active | F13: O | H13: O | L13: O | M13: O | N13: O | O13: O | P13: O | Q13: O | R13: O
D14: does not exist | G14: O
D15: inactive | J15: O
D16: locked | I16: O
D17: temporary password > 72 h | K17: O
B18: Password
D19: correct | F19: O | G19: O | I19: O | J19: O | K19: O | L19: O | M19: O | N19: O | O19: O | P19: O | Q19: O | R19: O
D20: wrong | H20: O
B21: Two-factor
D22: disabled | F22: O
D23: enabled, no code | L23: O
D24: enabled, wrong TOTP | M24: O
D25: enabled, valid TOTP | N25: O
D26: enabled, MFA secret empty | O26: O
D27: enabled, trusted device | P27: O
D28: enabled, valid backup code | Q28: O
D29: enabled, wrong backup code | R29: O
A30: Confirm | B30: Return
D31: token pair | F31: O | N31: O | P31: O | Q31: O
D32: { mfa_required: true } | L32: O
D33: new trusted_device_token | N33: O
D34: backup code removed | Q34: O
B35: Exception
D36: 401 Unauthorized | G36: O | H36: O | J36: O | M36: O | O36: O | R36: O
D37: 403 AUTH_ACCOUNT_LOCKED | I37: O
D38: 403 password deadline | K38: O
B39: Log message
D40: Test name in auth.service.spec.ts (line) | F40: line 115 | G40: line 140 | H40: line 153 | I40: line 170 | J40: line 181 | K40: line 197 | L40: line 217 | M40: line 235 | N40: line 254 | O40: line 276 | P40: line 295 | Q40: line 317 | R40: line 338
A41: Result | B41: Type(N : Normal, A : Abnormal, B : Boundary) | F41: N | G41: A | H41: A | I41: A | J41: A | K41: B | L41: N | M41: A | N41: N | O41: A | P41: N | Q41: N | R41: A
B42: Passed/Failed | F42: P | G42: P | H42: P | I42: P | J42: P | K42: P | L42: P | M42: P | N42: P | O42: P | P42: P | Q42: P | R42: P
...

Sheet UT-PICK-ITEM
A2: Function Code | C2: UT-PICK-ITEM | F2: Function Name | L2: OrderGroupsService.pickItem
A3: Created By | C3: Thi, Thuận | F3: Executed By | L3: GitHub Actions CI (run #258, commit 1a3101c)
A4: Lines of code | C4: 207 | F4: Lack of test cases | L4: =IF(Functions!E6<>"N/A",SUM(C4*Functions!E6/1000,-O7),"N/A")
A5: Test requirement | C5: Scan one item while picking: SKU of the group, ordered quantity, FIFO lot, idempotent scan – SRS 3.5.1. Test file: be/src/modules/order-groups/order-groups.service.pickItem.spec.ts; source: be/src/modules/order-groups/order-groups.service.ts
A6: Passed | C6: Failed | F6: Untested | L6: N/A/B | O6: Total Test Cases
A7: =COUNTIF(F43:M43,"P") | C7: =COUNTIF(F43:M43,"F") | F7: =SUM(O7,-A7,-C7) | L7: =COUNTIF(F42:M42,"N") | M7: =COUNTIF(F42:M42,"A") | N7: =COUNTIF(F42:M42,"B") | O7: =COUNTA(F9:M9)
F9: UTCID01 | G9: UTCID02 | H9: UTCID03 | I9: UTCID04 | J9: UTCID05 | K9: UTCID06 | L9: UTCID07 | M9: UTCID08
A10: Condition | B10: Precondition
D11: MongoDB transaction available (mocked) | F11: O | G11: O | H11: O | I11: O | J11: O | K11: O | L11: O | M11: O
B12: Group status
D13: picking | F13: O | G13: O | H13: O | I13: O | J13: O | K13: O | M13: O
D14: not picking | L14: O
B15: Scanned SKU
D16: in group | G16: O | H16: O | J16: O | K16: O | L16: O | M16: O
D17: not in group | F17: O
D18: same SKU in another shop | I18: O
B19: Quantity
D20: ≤ ordered | G20: O | H20: O | I20: O | J20: O
D21: > ordered | K21: O
B22: Bin
D23: given | G23: O
D24: not given (oldest lot) | J24: O
B25: client_event_id
D26: new | F26: O | G26: O | H26: O | I26: O | J26: O | K26: O | L26: O
D27: already processed | M27: O
B28: Scan
D29: first of the group | H29: O
D30: later scan | G30: O
A31: Confirm | B31: Return
D32: stock decremented + pick_event | G32: O | H32: O | I32: O | J32: O
D33: lot recorded on pick_event | J33: O
D34: website "preparing" event once | H34: O
D35: previous result returned | M35: O
B36: Exception
D37: ORD_GROUP_ITEM_NOT_IN_GROUP | F37: O
D38: ORD_GROUP_PICK_EXCEEDS_ORDERED | K38: O
D39: ORD_GROUP_PICK_NOT_ALLOWED | L39: O
B40: Log message
D41: Test name in order-groups.service.pickItem.spec.ts (line) | F41: line 131 | G41: line 143 | H41: line 174 | I41: line 194 | J41: line 216 | K41: line 286 | L41: line 299 | M41: line 309
A42: Result | B42: Type(N : Normal, A : Abnormal, B : Boundary) | F42: A | G42: N | H42: N | I42: N | J42: N | K42: B | L42: A | M42: N
...

Sheet UT-GROUP-TRANS
A2: Function Code | C2: UT-GROUP-TRANS | F2: Function Name | L2: allowed-status-transitions.isValidStatusTransition / getAllowedNextStatuses
A3: Created By | C3: Thi, Thuận | F3: Executed By | L3: GitHub Actions CI (run #258, commit 1a3101c)
A4: Lines of code | C4: 113 | F4: Lack of test cases | L4: =IF(Functions!E6<>"N/A",SUM(C4*Functions!E6/1000,-O7),"N/A")
A5: Test requirement | C5: Allowed Order Group status transitions (33) and rejection of invalid jumps – SDD 3.8. Test file: be/src/modules/order-groups/enums/allowed-status-transitions.spec.ts; source: be/src/modules/order-groups/enums/allowed-status-transitions.ts
A6: Passed | C6: Failed | F6: Untested | L6: N/A/B | O6: Total Test Cases
A7: =COUNTIF(F29:M29,"P") | C7: =COUNTIF(F29:M29,"F") | F7: =SUM(O7,-A7,-C7) | L7: =COUNTIF(F28:M28,"N") | M7: =COUNTIF(F28:M28,"A") | N7: =COUNTIF(F28:M28,"B") | O7: =COUNTA(F9:M9)
F9: UTCID01 | G9: UTCID02 | H9: UTCID03 | I9: UTCID04 | J9: UTCID05 | K9: UTCID06 | L9: UTCID07 | M9: UTCID08
A10: Condition | B10: Precondition
D11: Pure function, no external dependency | F11: O | G11: O | H11: O | I11: O | J11: O | K11: O | L11: O | M11: O
B12: From → to
D13: happy path step (e.g. picking → picked) | F13: O
D14: pending_approval → picked | G14: O
D15: packed → canceled | H15: O
D16: shipped → packed | I16: O
D17: awaiting_packaging → packed | J17: O
D18: packed → packed | K18: O
D19: shipped → canceled | L19: O
D20: canceled → any | M20: O
A21: Confirm | B21: Return
D22: true | F22: O | G22: O | H22: O | I22: O
D23: false | J23: O | K23: O | L23: O
D24: [] (no next status) | M24: O
B25: Exception
B26: Log message
D27: Test name in allowed-status-transitions.spec.ts (line) | F27: line 29 | G27: line 35 | H27: line 154 | I27: line 176 | J27: line 115 | K27: line 115 | L27: line 147 | M27: line 164
A28: Result | B28: Type(N : Normal, A : Abnormal, B : Boundary) | F28: N | G28: N | H28: N | I28: N | J28: A | K28: B | L28: A | M28: B
B29: Passed/Failed | F29: P | G29: P | H29: P | I29: P | J29: P | K29: P | L29: P | M29: P
B30: Executed Date | F30: 25/10/2026 | G30: 25/10/2026 | H30: 25/10/2026 | I30: 25/10/2026 | J30: 25/10/2026 | K30: 25/10/2026 | L30: 25/10/2026 | M30: 25/10/2026

Sheet UT-RETURNS
A2: Function Code | C2: UT-RETURNS | F2: Function Name | L2: ReturnsService.createSimulated / approve / reject / receive / inspect
A3: Created By | C3: Thi, Thuận | F3: Executed By | L3: GitHub Actions CI (run #258, commit 1a3101c)
A4: Lines of code | C4: 351 | F4: Lack of test cases | L4: =IF(Functions!E6<>"N/A",SUM(C4*Functions!E6/1000,-O7),"N/A")
A5: Test requirement | C5: Return ticket rules: 15-day window, one open ticket, no self-approval, reason required, inspection – SRS 3.8, BR-11, BR-12. Test file: be/src/modules/shipments/returns.service.spec.ts; source: be/src/modules/shipments/returns.service.ts
A6: Passed | C6: Failed | F6: Untested | L6: N/A/B | O6: Total Test Cases
A7: =COUNTIF(F52:Q52,"P") | C7: =COUNTIF(F52:Q52,"F") | F7: =SUM(O7,-A7,-C7) | L7: =COUNTIF(F51:Q51,"N") | M7: =COUNTIF(F51:Q51,"A") | N7: =COUNTIF(F51:Q51,"B") | O7: =COUNTA(F9:Q9)
F9: UTCID01 | G9: UTCID02 | H9: UTCID03 | I9: UTCID04 | J9: UTCID05 | K9: UTCID06 | L9: UTCID07 | M9: UTCID08 | N9: UTCID09 | O9: UTCID10 | P9: UTCID11 | Q9: UTCID12
A10: Condition | B10: Precondition
D11: MongoDB transaction available (mocked) | F11: O | G11: O | H11: O | I11: O | J11: O | K11: O | L11: O | M11: O | N11: O | O11: O | P11: O | Q11: O
B12: Order group
D13: delivered ≤ 15 days | I13: O | J13: O | K13: O
D14: delivered > 15 days | H14: O
D15: not delivered | G15: O
D16: AURELLE (marketplace-managed) | F16: O
B17: Ticket
D18: none open | F18: O | G18: O | H18: O | I18: O | K18: O
D19: open ticket exists | J19: O
D20: requested | L20: O | M20: O | N20: O | O20: O | P20: O
D21: approved (awaiting receipt) | Q21: O
B22: Items
D23: valid | F23: O | G23: O | H23: O | J23: O | K23: O
D24: more than bought / unknown SKU | I24: O
D25: inspected fewer than returned | Q25: O
B26: Actor
D27: creator | L27: O
D28: other user | M28: O | N28: O | O28: O
B29: Note
D30: given
D31: missing | O31: O
B32: Type
D33: return & refund | N33: O
D34: refund only | M34: O
A35: Confirm | B35: Return
D36: ticket "requested" | K36: O
D37: ticket closed | M37: O
D38: ticket awaiting_receipt | N38: O
B39: Exception
D40: 409 RMA_MARKETPLACE_MANAGED | F40: O
D41: 409 RMA_ORDER_NOT_DELIVERED | G41: O
D42: 409 RMA_WINDOW_EXPIRED | H42: O
...

Sheet UT-SOLVER
A2: Function Code | C2: UT-SOLVER | F2: Function Name | L2: solve-order (BRKGA + EMS).solveOrder
A3: Created By | C3: Thi | F3: Executed By | L3: GitHub Actions CI (run #258, commit 1a3101c)
A4: Lines of code | C4: 590 | F4: Lack of test cases | L4: =IF(Functions!E6<>"N/A",SUM(C4*Functions!E6/1000,-O7),"N/A")
A5: Test requirement | C5: 3D packing plan per order: valid placement, determinism, fragile items, folding, box stock and exclusions – SRS 3.6.1, BR-06, BR-15. Test file: be/src/modules/packing/solver/solver.spec.ts; source: be/src/modules/packing/solver/solve-order.ts
A6: Passed | C6: Failed | F6: Untested | L6: N/A/B | O6: Total Test Cases
A7: =COUNTIF(F42:O42,"P") | C7: =COUNTIF(F42:O42,"F") | F7: =SUM(O7,-A7,-C7) | L7: =COUNTIF(F41:O41,"N") | M7: =COUNTIF(F41:O41,"A") | N7: =COUNTIF(F41:O41,"B") | O7: =COUNTA(F9:O9)
F9: UTCID01 | G9: UTCID02 | H9: UTCID03 | I9: UTCID04 | J9: UTCID05 | K9: UTCID06 | L9: UTCID07 | M9: UTCID08 | N9: UTCID09 | O9: UTCID10
A10: Condition | B10: Precondition
D11: Box catalog with stock (fixture) | F11: O | G11: O | H11: O | I11: O | J11: O | K11: O | L11: O | M11: O | N11: O | O11: O
B12: Order
D13: random items (25 orders) | F13: O
D14: fixed small order | G14: O | L14: O | M14: O | N14: O
D15: ≤ 3 items | H15: O
D16: > 3 items | I16: O
D17: fragile item | J17: O
D18: jean 26 cm wide (box M 25 cm) | K18: O
D19: oversize / overweight item | O19: O
B20: Run
D21: same input twice | G21: O
B22: Box stock
D23: all in stock | F23: O | G23: O | H23: O | I23: O | J23: O | K23: O | O23: O
D24: best box out of stock | L24: O
D25: box excluded | M25: O
D26: all fitting boxes out of stock | N26: O
A27: Confirm | B27: Return
D28: plan passes validator | F28: O
D29: identical coordinates | G29: O
D30: exhaustive search | H30: O
D31: BRKGA | I31: O
D32: nothing on top of fragile item | J32: O
D33: item folded to use box M | K33: O
D34: another box used | L34: O
D35: excluded box not used | M35: O
B36: Exception
D37: OUT_OF_STOCK | N37: O
D38: ITEM_TOO_LARGE / ITEM_TOO_HEAVY | O38: O
B39: Log message
D40: Test name in solver.spec.ts (line) | F40: line 41 | G40: line 58 | H40: line 67 | I40: line 67 | J40: line 79 | K40: line 110 | L40: line 125 | M40: line 133 | N40: line 138 | O40: line 146
A41: Result | B41: Type(N : Normal, A : Abnormal, B : Boundary) | F41: N | G41: N | H41: B | I41: B | J41: N | K41: B | L41: A | M41: A | N41: A | O41: A
B42: Passed/Failed | F42: P | G42: P | H42: P | I42: P | J42: P | K42: P | L42: P | M42: P | N42: P | O42: P
...
