Workbook
Name ACTION: #REF!
Name ACTION: #REF!

Sheet Cover
B2: TEST REPORT DOCUMENT
A4: Project Name | B4: Develop an AI-Assisted Omnichannel Order Fulfillment and Packaging Optimization System (OptiPack AI) | E4: Creator | F4: Nguyễn Phương Mỹ Thuận
A5: Project Code | B5: FA26SE036 | E5: Issue Date | F5: 25/10/2026
A6: Document Code | B6: =B5&"_"&"Test Report"&"_"&"v1.0" | E6: Version | F6: 1.0
A9: Record of change
A10: Effective Date | B10: Version | C10: Change Item | D10: *A,D,M | E10: Change description | F10: Reference
A11: 25/10/2026 | B11: 1.0 | C11: Whole document | D11: A | E11: Initial test report for Review 2: 75 functional test cases (10 mandatory features × 3, 6 main workflows, 33 Order Group state transitions, 6 NFRs); round 1 results from CI run #258 on tag review-2. | F11: Report 3 (SRS), Report 4 (SDD), Design Brief BM01, Report5_Test_Documentation.docx

Sheet Test Cases
D1: TEST CASE LIST
B3: Project Name | D3: Develop an AI-Assisted Omnichannel Order Fulfillment and Packaging Optimization System (OptiPack AI)
B4: Project Code | D4: FA26SE036
B5: Test Environment Setup Description | D5: 1. Server: back end NestJS 11 on Node.js 22 (CI: ubuntu-latest, GitHub Actions); packer service Python 3.12 / FastAPI (optional) 2. Database: MongoDB Atlas (replica set, transactions); Redis 7 (Docker) 3. Web browser: Chrome (latest) for the staff portal (React 19 + Vite) and the AURELLE website (Next.js 15) 4. External: Lazada test shop, AURELLE Open API simulator (be/scripts/aurelle-mock-server.ts), GHN staging API 5. Data: seeded with be/scripts/seed-*.ts
B8: No | C8: Function Name | D8: Sheet Name | E8: Description | F8: Pre-Condition
B9: 1 | C9: F-01 Authentication and role-based access | D9: F-01 | E9: Acceptance criteria of F-01 (Design Brief section 6): main flow, data / business rule, exception or permission | F9: Logged in with a role allowed for the feature
B10: 2 | C10: F-02 Marketplace connection and order sync | D10: F-02 | E10: Acceptance criteria of F-02 (Design Brief section 6): main flow, data / business rule, exception or permission | F10: Logged in with a role allowed for the feature
B11: 3 | C11: F-03 Order consolidation and groups | D11: F-03 | E11: Acceptance criteria of F-03 (Design Brief section 6): main flow, data / business rule, exception or permission | F11: Logged in with a role allowed for the feature
B12: 4 | C12: F-04 Stock reservation and FIFO lots | D12: F-04 | E12: Acceptance criteria of F-04 (Design Brief section 6): main flow, data / business rule, exception or permission | F12: Logged in with a role allowed for the feature
B13: 5 | C13: F-05 Picking with missing-item handling | D13: F-05 | E13: Acceptance criteria of F-05 (Design Brief section 6): main flow, data / business rule, exception or permission | F13: Logged in with a role allowed for the feature
B14: 6 | C14: F-06 3D packing plan, approval and packing | D14: F-06 | E14: Acceptance criteria of F-06 (Design Brief section 6): main flow, data / business rule, exception or permission | F14: Logged in with a role allowed for the feature
B15: 7 | C15: F-07 Shipping with GHN | D15: F-07 | E15: Acceptance criteria of F-07 (Design Brief section 6): main flow, data / business rule, exception or permission | F15: Logged in with a role allowed for the feature
B16: 8 | C16: F-08 Returns and exchanges | D16: F-08 | E16: Acceptance criteria of F-08 (Design Brief section 6): main flow, data / business rule, exception or permission | F16: Logged in with a role allowed for the feature
B17: 9 | C17: F-09 AURELLE web store and order tracking | D17: F-09 | E17: Acceptance criteria of F-09 (Design Brief section 6): main flow, data / business rule, exception or permission | F17: Logged in with a role allowed for the feature
B18: 10 | C18: F-10 Documents and labels | D18: F-10 | E18: Acceptance criteria of F-10 (Design Brief section 6): main flow, data / business rule, exception or permission | F18: Logged in with a role allowed for the feature
B19: 11 | C19: Main workflows (end-to-end) | D19: WF | E19: One end-to-end main scenario per main workflow WF-01 … WF-06 (Design Brief A1 / A2) | F19: Staging with seeded data; all roles available
B20: 12 | C20: Order Group state transitions | D20: ST | E20: Every allowed transition of the Order Group (be/src/modules/order-groups/enums/allowed-status-transitions.ts, 33 transitions); invalid jumps are rejected | F20: Order Group in the source status
B21: 13 | C21: Non-functional requirements | D21: NFR | E21: Each agreed NFR measured with its metric and threshold (Design Brief section 7) | F21: See each case

Sheet Test Statistics
B1: TEST STATISTICS
B3: Project Name | C3: Develop an AI-Assisted Omnichannel Order Fulfillment and Packaging Optimization System (OptiPack AI) | E3: Creator | G3: Nguyễn Phương Mỹ Thuận
B4: Project Code | C4: FA26SE036 | E4: Reviewer/Approver | G4: Thân Thị Ngọc Vân
B5: Document Code | C5: =C4&"_"&"Test Report"&"_"&"v1.0" | E5: Issue Date | H5: 25/10/2026
B6: Notes | C6: Review 2 release (tag review-2, commit 1a3101c): 10 mandatory features F-01 … F-10, main workflows WF-01 … WF-06, Order Group state transitions, NFR-1 … NFR-6. Round 1 = automated results of CI run #258; manual cases are pending until the Verification stage.
B10: No | C10: Module code | D10: Passed | E10: Failed | F10: Pending | G10: N/A | H10: Number of test cases
B11: 1 | C11: ='F-01'!B2 | D11: ='F-01'!B6 | E11: ='F-01'!C6 | F11: ='F-01'!D6 | G11: ='F-01'!E6 | H11: ='F-01'!B4
B12: 2 | C12: ='F-02'!B2 | D12: ='F-02'!B6 | E12: ='F-02'!C6 | F12: ='F-02'!D6 | G12: ='F-02'!E6 | H12: ='F-02'!B4
B13: 3 | C13: ='F-03'!B2 | D13: ='F-03'!B6 | E13: ='F-03'!C6 | F13: ='F-03'!D6 | G13: ='F-03'!E6 | H13: ='F-03'!B4
B14: 4 | C14: ='F-04'!B2 | D14: ='F-04'!B6 | E14: ='F-04'!C6 | F14: ='F-04'!D6 | G14: ='F-04'!E6 | H14: ='F-04'!B4
B15: 5 | C15: ='F-05'!B2 | D15: ='F-05'!B6 | E15: ='F-05'!C6 | F15: ='F-05'!D6 | G15: ='F-05'!E6 | H15: ='F-05'!B4
B16: 6 | C16: ='F-06'!B2 | D16: ='F-06'!B6 | E16: ='F-06'!C6 | F16: ='F-06'!D6 | G16: ='F-06'!E6 | H16: ='F-06'!B4
B17: 7 | C17: ='F-07'!B2 | D17: ='F-07'!B6 | E17: ='F-07'!C6 | F17: ='F-07'!D6 | G17: ='F-07'!E6 | H17: ='F-07'!B4
B18: 8 | C18: ='F-08'!B2 | D18: ='F-08'!B6 | E18: ='F-08'!C6 | F18: ='F-08'!D6 | G18: ='F-08'!E6 | H18: ='F-08'!B4
B19: 9 | C19: ='F-09'!B2 | D19: ='F-09'!B6 | E19: ='F-09'!C6 | F19: ='F-09'!D6 | G19: ='F-09'!E6 | H19: ='F-09'!B4
B20: 10 | C20: ='F-10'!B2 | D20: ='F-10'!B6 | E20: ='F-10'!C6 | F20: ='F-10'!D6 | G20: ='F-10'!E6 | H20: ='F-10'!B4
B21: 11 | C21: ='WF'!B2 | D21: ='WF'!B6 | E21: ='WF'!C6 | F21: ='WF'!D6 | G21: ='WF'!E6 | H21: ='WF'!B4
B22: 12 | C22: ='ST'!B2 | D22: ='ST'!B6 | E22: ='ST'!C6 | F22: ='ST'!D6 | G22: ='ST'!E6 | H22: ='ST'!B4
B23: 13 | C23: ='NFR'!B2 | D23: ='NFR'!B6 | E23: ='NFR'!C6 | F23: ='NFR'!D6 | G23: ='NFR'!E6 | H23: ='NFR'!B4
C25: Sub total | D25: =SUM(D11:D23) | E25: =SUM(E11:E23) | F25: =SUM(F11:F23) | G25: =SUM(G11:G23) | H25: =SUM(H11:H23)
C27: Test coverage | E27: =(D25+E25)*100/(H25-G25) | F27: %
C28: Test successful coverage | E28: =D25*100/(H25-G25) | F28: %
C29: Automated in CI | E29: 61 | F29: of 75 test cases

Sheet F-01
A2: Feature | B2: F-01 Authentication and role-based access | T2: Passed
A3: Test requirement | B3: Acceptance criteria of F-01 (Design Brief section 6): main flow, data / business rule, exception or permission | T3: Failed
A4: Number of TCs | B4: =COUNTA(A12:A1000)-COUNTIF(A12:A1000,"►*") | T4: Pending
A5: Testing Round | B5: Passed | C5: Failed | D5: Pending | E5: N/A | T5: N/A
A6: Round 1 | B6: =COUNTIF($F$12:$F$1000,B$5) | C6: =COUNTIF($F$12:$F$1000,C$5) | D6: =COUNTIF($F$12:$F$1000,D$5) | E6: =COUNTIF($F$12:$F$1000,E$5)
A7: Round 2 | B7: =COUNTIF($I$12:$I$1000,B$5) | C7: =COUNTIF($I$12:$I$1000,C$5) | D7: =COUNTIF($I$12:$I$1000,D$5) | E7: =COUNTIF($I$12:$I$1000,E$5)
A8: Round 3 | B8: =COUNTIF($L$12:$L$1000,B$5) | C8: =COUNTIF($L$12:$L$1000,C$5) | D8: =COUNTIF($L$12:$L$1000,D$5) | E8: =COUNTIF($L$12:$L$1000,E$5)
A10: Test Case ID | B10: Test Case Description | C10: Test Case Procedure | D10: Expected Results | E10: Pre-conditions | F10: Round 1 | G10: Test date | H10: Tester | I10: Round 2 | J10: Test date | K10: Tester | L10: Round 3 | M10: Test date | N10: Tester | O10: Note | P10: Test data | Q10: Run method / evidence | R10: Actual result
A11: ► F-01 Authentication and role-based access
A12: TC-F01-01 | B12: [Main] Log in with correct e-mail and password (two-factor not enabled) | C12: 1. Open /login 2. Enter e-mail and password 3. Press Log in | D12: Access and refresh tokens are issued; the home screen of the role opens | E12: Active staff account, MFA off | F12: Passed | G12: 25/10/2026 | H12: GitHub Actions CI | O12: login success without MFA returns a token pair | P12: admin@optipackai.com / valid password | Q12: Automated (Jest, CI) – be/src/modules/auth/auth.service.spec.ts:115 | R12: Passed in CI (GitHub Actions run #258, commit 1a3101c, 25/10/2026)
A13: TC-F01-02 | B13: [Rule] Wrong password increases the failed-attempt counter; a locked account is refused | C13: 1. Enter a wrong password 2. Repeat until the account is locked 3. Log in again with the right password | D13: Each wrong password returns 401 and increments failed_login_attempts; a locked account returns 403 before the password is checked | E13: Active staff account | F13: Passed | G13: 25/10/2026 | H13: GitHub Actions CI | O13: wrong password → 401 and counter increased; locked account → 403 (line 170) | P13: Wrong password ×5 | Q13: Automated (Jest, CI) – be/src/modules/auth/auth.service.spec.ts:153 | R13: Passed in CI (GitHub Actions run #258, commit 1a3101c, 25/10/2026)
A14: TC-F01-03 | B14: [Permission] A role calls an API outside its permissions | C14: 1. Log in as Warehouse Staff 2. Call an Admin-only endpoint | D14: HTTP 403; the handler is not executed | E14: Route protected by @Roles(Admin) | F14: Passed | G14: 25/10/2026 | H14: GitHub Actions CI | O14: route with @Roles(), user with the wrong role → 403 | P14: Role = WAREHOUSE_STAFF | Q14: Automated (Jest, CI) – be/src/modules/auth/guards/roles.guard.spec.ts:45 | R14: Passed in CI (GitHub Actions run #258, commit 1a3101c, 25/10/2026)

Sheet F-02
A2: Feature | B2: F-02 Marketplace connection and order sync | T2: Passed
A3: Test requirement | B3: Acceptance criteria of F-02 (Design Brief section 6): main flow, data / business rule, exception or permission | T3: Failed
A4: Number of TCs | B4: =COUNTA(A12:A1000)-COUNTIF(A12:A1000,"►*") | T4: Pending
A5: Testing Round | B5: Passed | C5: Failed | D5: Pending | E5: N/A | T5: N/A
A6: Round 1 | B6: =COUNTIF($F$12:$F$1000,B$5) | C6: =COUNTIF($F$12:$F$1000,C$5) | D6: =COUNTIF($F$12:$F$1000,D$5) | E6: =COUNTIF($F$12:$F$1000,E$5)
A7: Round 2 | B7: =COUNTIF($I$12:$I$1000,B$5) | C7: =COUNTIF($I$12:$I$1000,C$5) | D7: =COUNTIF($I$12:$I$1000,D$5) | E7: =COUNTIF($I$12:$I$1000,E$5)
A8: Round 3 | B8: =COUNTIF($L$12:$L$1000,B$5) | C8: =COUNTIF($L$12:$L$1000,C$5) | D8: =COUNTIF($L$12:$L$1000,D$5) | E8: =COUNTIF($L$12:$L$1000,E$5)
A10: Test Case ID | B10: Test Case Description | C10: Test Case Procedure | D10: Expected Results | E10: Pre-conditions | F10: Round 1 | G10: Test date | H10: Tester | I10: Round 2 | J10: Test date | K10: Tester | L10: Round 3 | M10: Test date | N10: Tester | O10: Note | P10: Test data | Q10: Run method / evidence | R10: Actual result
A11: ► F-02 Marketplace connection and order sync
A12: TC-F02-01 | B12: [Main] The scheduler synchronizes a Lazada shop whose sync interval has passed | C12: 1. Set the sync interval to 30 min and turn AURELLE auto-sync off 2. Scheduler tick (every minute) 3. Check which shops are synchronized | D12: Only the due and never-polled Lazada shops are synchronized; the not-due shop waits for its interval; AURELLE is not scanned | E12: Lazada shops connected | F12: Passed | G12: 25/10/2026 | H12: GitHub Actions CI | O12: scheduler syncs only shops that are due and platforms that are enabled | P12: Interval 30 min; shop due (last polled 31 min ago), shop not-due (10 min ago), shop never polled; AURELLE auto-sync off | Q12: Automated (Jest, CI) – be/src/modules/orders/order-sync-settings.spec.ts:179 | R12: Passed in CI (GitHub Actions run #258, commit 1a3101c, 25/10/2026)
A13: TC-F02-02 | B13: [Rule] The same webhook event delivered twice creates no second order | C13: 1. Send a webhook 2. Send the same message_id again | D13: Second delivery is acknowledged (200) without a new sync | E13: Event already processed | F13: Passed | G13: 25/10/2026 | H13: GitHub Actions CI | O13: already processed message_id → ack, no second sync | P13: Duplicate message_id | Q13: Automated (Jest, CI) – be/src/modules/marketplace-webhooks/marketplace-webhooks.service.spec.ts:82 | R13: Passed in CI (GitHub Actions run #258, commit 1a3101c, 25/10/2026)
A14: TC-F02-03 | B14: [Exception] Webhook with an invalid signature is rejected | C14: 1. Send a webhook with a wrong HMAC signature | D14: 401 MKT_WEBHOOK_SIGNATURE_INVALID; nothing is recorded or synchronized | E14: AURELLE app secret configured | F14: Passed | G14: 25/10/2026 | H14: GitHub Actions CI | O14: wrong signature → 401, no dedupe record, no sync | P14: Wrong signature | Q14: Automated (Jest, CI) – be/src/modules/marketplace-webhooks/marketplace-webhooks.service.spec.ts:55 | R14: Passed in CI (GitHub Actions run #258, commit 1a3101c, 25/10/2026)

Sheet F-03
A2: Feature | B2: F-03 Order consolidation and groups | T2: Passed
A3: Test requirement | B3: Acceptance criteria of F-03 (Design Brief section 6): main flow, data / business rule, exception or permission | T3: Failed
A4: Number of TCs | B4: =COUNTA(A12:A1000)-COUNTIF(A12:A1000,"►*") | T4: Pending
A5: Testing Round | B5: Passed | C5: Failed | D5: Pending | E5: N/A | T5: N/A
A6: Round 1 | B6: =COUNTIF($F$12:$F$1000,B$5) | C6: =COUNTIF($F$12:$F$1000,C$5) | D6: =COUNTIF($F$12:$F$1000,D$5) | E6: =COUNTIF($F$12:$F$1000,E$5)
A7: Round 2 | B7: =COUNTIF($I$12:$I$1000,B$5) | C7: =COUNTIF($I$12:$I$1000,C$5) | D7: =COUNTIF($I$12:$I$1000,D$5) | E7: =COUNTIF($I$12:$I$1000,E$5)
A8: Round 3 | B8: =COUNTIF($L$12:$L$1000,B$5) | C8: =COUNTIF($L$12:$L$1000,C$5) | D8: =COUNTIF($L$12:$L$1000,D$5) | E8: =COUNTIF($L$12:$L$1000,E$5)
A10: Test Case ID | B10: Test Case Description | C10: Test Case Procedure | D10: Expected Results | E10: Pre-conditions | F10: Round 1 | G10: Test date | H10: Tester | I10: Round 2 | J10: Test date | K10: Tester | L10: Round 3 | M10: Test date | N10: Tester | O10: Note | P10: Test data | Q10: Run method / evidence | R10: Actual result
A11: ► F-03 Order consolidation and groups
A12: TC-F03-01 | B12: [Main] A new order joins the open group of the same recipient | C12: 1. Import order A 2. Import order B with the same phone, address and city | D12: Order B is added to the group of order A | E12: Group of order A is still open | F12: Passed | G12: 25/10/2026 | H12: GitHub Actions CI | O12: sibling in an open group → joined to that group | P12: Same consolidation key | Q12: Automated (Jest, CI) – be/src/modules/orders/orders.service.tryConsolidate.spec.ts:93 | R12: Passed in CI (GitHub Actions run #258, commit 1a3101c, 25/10/2026)
A13: TC-F03-02 | B13: [Rule] A group that is already picked does not accept late orders | C13: 1. Pick group of order A 2. Import order B with the same key | D13: Order B stays standalone (new group) | E13: Group status picked or later | F13: Passed | G13: 25/10/2026 | H13: GitHub Actions CI | O13: sibling in a locked group (picked onward) → not merged | P13: Same consolidation key | Q13: Automated (Jest, CI) – be/src/modules/orders/orders.service.tryConsolidate.spec.ts:83 | R13: Passed in CI (GitHub Actions run #258, commit 1a3101c, 25/10/2026)
A14: TC-F03-03 | B14: [Exception] Split a group after an item has been scanned | C14: 1. Scan one item of the group 2. Split one order out of the group | D14: 409 REGROUP_HAS_PICKS; data unchanged | E14: Group in picking with a scan | F14: Passed | G14: 25/10/2026 | H14: GitHub Actions CI | O14: already scanned in the current round → 409 REGROUP_HAS_PICKS | P14: Split request with reason | Q14: Automated (Jest, CI) – be/src/modules/order-groups/order-groups.service.regroup.spec.ts:138 | R14: Passed in CI (GitHub Actions run #258, commit 1a3101c, 25/10/2026)

Sheet F-04
A2: Feature | B2: F-04 Stock reservation and FIFO lots | T2: Passed
A3: Test requirement | B3: Acceptance criteria of F-04 (Design Brief section 6): main flow, data / business rule, exception or permission | T3: Failed
A4: Number of TCs | B4: =COUNTA(A12:A1000)-COUNTIF(A12:A1000,"►*") | T4: Pending
A5: Testing Round | B5: Passed | C5: Failed | D5: Pending | E5: N/A | T5: N/A
A6: Round 1 | B6: =COUNTIF($F$12:$F$1000,B$5) | C6: =COUNTIF($F$12:$F$1000,C$5) | D6: =COUNTIF($F$12:$F$1000,D$5) | E6: =COUNTIF($F$12:$F$1000,E$5)
A7: Round 2 | B7: =COUNTIF($I$12:$I$1000,B$5) | C7: =COUNTIF($I$12:$I$1000,C$5) | D7: =COUNTIF($I$12:$I$1000,D$5) | E7: =COUNTIF($I$12:$I$1000,E$5)
A8: Round 3 | B8: =COUNTIF($L$12:$L$1000,B$5) | C8: =COUNTIF($L$12:$L$1000,C$5) | D8: =COUNTIF($L$12:$L$1000,D$5) | E8: =COUNTIF($L$12:$L$1000,E$5)
A10: Test Case ID | B10: Test Case Description | C10: Test Case Procedure | D10: Expected Results | E10: Pre-conditions | F10: Round 1 | G10: Test date | H10: Tester | I10: Round 2 | J10: Test date | K10: Tester | L10: Round 3 | M10: Test date | N10: Tester | O10: Note | P10: Test data | Q10: Run method / evidence | R10: Actual result
A11: ► F-04 Stock reservation and FIFO lots
A12: TC-F04-01 | B12: [Main] A new group reserves available bin stock | C12: 1. Import an order for a SKU with stock 2. Check the reservation | D12: 1 unit reserved, no shortage flag | E12: Bin stock 1, nobody reserved | F12: Passed | G12: 25/10/2026 | H12: GitHub Actions CI | O12: group 1: bin has 1, nothing reserved → reserves 1, no shortage | P12: Order quantity 1 | Q12: Automated (Jest, CI) – be/src/modules/order-groups/stock-reservation.service.spec.ts:33 | R12: Passed in CI (GitHub Actions run #258, commit 1a3101c, 25/10/2026)
A13: TC-F04-02 | B13: [Rule] Picking consumes the oldest lot first | C13: 1. Receive lot 1 (2 units) and later lot 2 2. Pick 3 units | D13: Lot 1 is emptied first, then 1 unit from lot 2 | E13: Two lots with different dates | F13: Passed | G13: 25/10/2026 | H13: GitHub Actions CI | O13: 2 lots, take 3 → old lot (2) first, then 1 from the new lot | P13: Lot 1 = 2, lot 2 = 2; pick 3 | Q13: Automated (Jest, CI) – be/src/modules/warehouse/stock-lot.ledger.spec.ts:149 | R13: Passed in CI (GitHub Actions run #258, commit 1a3101c, 25/10/2026)
A14: TC-F04-03 | B14: [Exception] A second group cannot reserve stock already reserved by another group | C14: 1. Group 1 reserves the last unit 2. Import group 2 for the same SKU | D14: Group 2 reserves 0 and is flagged stock shortage | E14: Bin stock 1 reserved by group 1 | F14: Passed | G14: 25/10/2026 | H14: GitHub Actions CI | O14: group 2: stock already reserved → reserves 0, stock-shortage flag | P14: Order quantity 1 | Q14: Automated (Jest, CI) – be/src/modules/order-groups/stock-reservation.service.spec.ts:44 | R14: Passed in CI (GitHub Actions run #258, commit 1a3101c, 25/10/2026)

Sheet F-05
A2: Feature | B2: F-05 Picking with missing-item handling | T2: Passed
A3: Test requirement | B3: Acceptance criteria of F-05 (Design Brief section 6): main flow, data / business rule, exception or permission | T3: Failed
A4: Number of TCs | B4: =COUNTA(A12:A1000)-COUNTIF(A12:A1000,"►*") | T4: Pending
A5: Testing Round | B5: Passed | C5: Failed | D5: Pending | E5: N/A | T5: N/A
A6: Round 1 | B6: =COUNTIF($F$12:$F$1000,B$5) | C6: =COUNTIF($F$12:$F$1000,C$5) | D6: =COUNTIF($F$12:$F$1000,D$5) | E6: =COUNTIF($F$12:$F$1000,E$5)
A7: Round 2 | B7: =COUNTIF($I$12:$I$1000,B$5) | C7: =COUNTIF($I$12:$I$1000,C$5) | D7: =COUNTIF($I$12:$I$1000,D$5) | E7: =COUNTIF($I$12:$I$1000,E$5)
A8: Round 3 | B8: =COUNTIF($L$12:$L$1000,B$5) | C8: =COUNTIF($L$12:$L$1000,C$5) | D8: =COUNTIF($L$12:$L$1000,D$5) | E8: =COUNTIF($L$12:$L$1000,E$5)
A10: Test Case ID | B10: Test Case Description | C10: Test Case Procedure | D10: Expected Results | E10: Pre-conditions | F10: Round 1 | G10: Test date | H10: Tester | I10: Round 2 | J10: Test date | K10: Tester | L10: Round 3 | M10: Test date | N10: Tester | O10: Note | P10: Test data | Q10: Run method / evidence | R10: Actual result
A11: ► F-05 Picking with missing-item handling
A12: TC-F05-01 | B12: [Main] Scan the correct SKU of the group | C12: 1. Open Warehouse Picking 2. Scan an item of the group | D12: Bin stock is decremented and a pick event is written in the same transaction | E12: Group in picking, stock in bin | F12: Passed | G12: 25/10/2026 | H12: GitHub Actions CI | O12: correct SKU → stock decremented + event in one transaction | P12: SKU of the group | Q12: Automated (Jest, CI) – be/src/modules/order-groups/order-groups.service.pickItem.spec.ts:143 | R12: Passed in CI (GitHub Actions run #258, commit 1a3101c, 25/10/2026)
A13: TC-F05-02 | B13: [Rule] Scanning more than the ordered quantity is rejected | C13: 1. Scan a SKU beyond its ordered quantity | D13: ORD_GROUP_PICK_EXCEEDS_ORDERED; stock unchanged | E13: SKU already fully picked | F13: Passed | G13: 25/10/2026 | H13: GitHub Actions CI | O13: scan over ordered quantity → ORD_GROUP_PICK_EXCEEDS_ORDERED | P13: Extra scan | Q13: Automated (Jest, CI) – be/src/modules/order-groups/order-groups.service.pickItem.spec.ts:286 | R13: Passed in CI (GitHub Actions run #258, commit 1a3101c, 25/10/2026)
A14: TC-F05-03 | B14: [Exception] Confirm picking while items are missing | C14: 1. Scan only part of the items 2. Press Complete picking | D14: ORD_GROUP_PICK_INCOMPLETE with the list of missing items | E14: Group in picking | F14: Passed | G14: 25/10/2026 | H14: GitHub Actions CI | O14: confirmPicked with missing items → ORD_GROUP_PICK_INCOMPLETE | P14: Missing SKU | Q14: Automated (Jest, CI) – be/src/modules/order-groups/order-groups.service.pickItem.spec.ts:330 | R14: Passed in CI (GitHub Actions run #258, commit 1a3101c, 25/10/2026)

Sheet F-06
A2: Feature | B2: F-06 3D packing plan, approval and packing | T2: Passed
A3: Test requirement | B3: Acceptance criteria of F-06 (Design Brief section 6): main flow, data / business rule, exception or permission | T3: Failed
A4: Number of TCs | B4: =COUNTA(A12:A1000)-COUNTIF(A12:A1000,"►*") | T4: Pending
A5: Testing Round | B5: Passed | C5: Failed | D5: Pending | E5: N/A | T5: N/A
A6: Round 1 | B6: =COUNTIF($F$12:$F$1000,B$5) | C6: =COUNTIF($F$12:$F$1000,C$5) | D6: =COUNTIF($F$12:$F$1000,D$5) | E6: =COUNTIF($F$12:$F$1000,E$5)
A7: Round 2 | B7: =COUNTIF($I$12:$I$1000,B$5) | C7: =COUNTIF($I$12:$I$1000,C$5) | D7: =COUNTIF($I$12:$I$1000,D$5) | E7: =COUNTIF($I$12:$I$1000,E$5)
A8: Round 3 | B8: =COUNTIF($L$12:$L$1000,B$5) | C8: =COUNTIF($L$12:$L$1000,C$5) | D8: =COUNTIF($L$12:$L$1000,D$5) | E8: =COUNTIF($L$12:$L$1000,E$5)
A10: Test Case ID | B10: Test Case Description | C10: Test Case Procedure | D10: Expected Results | E10: Pre-conditions | F10: Round 1 | G10: Test date | H10: Tester | I10: Round 2 | J10: Test date | K10: Tester | L10: Round 3 | M10: Test date | N10: Tester | O10: Note | P10: Test data | Q10: Run method / evidence | R10: Actual result
A11: ► F-06 3D packing plan, approval and packing
A12: TC-F06-01 | B12: [Main] Compute packing plans for a picked group | C12: 1. Group reaches picked 2. Packing job computes the plan | D12: A ready plan for every order, parcels numbered 1..N, group → pending_approval, Packaging Staff notified | E12: All SKU profiles confirmed | F12: Passed | G12: 25/10/2026 | H12: GitHub Actions CI | O12: ready plan for every order, group → pending_approval | P12: Picked group | Q12: Automated (Jest, CI) – be/src/modules/packing/packing-plan.service.spec.ts:275 | R12: Passed in CI (GitHub Actions run #258, commit 1a3101c, 25/10/2026)
A13: TC-F06-02 | B13: [Rule] Nothing is placed on top of a fragile item | C13: 1. Compute a plan for an order with a fragile item | D13: No item is placed above the fragile item | E13: Fragile SKU in the order | F13: Passed | G13: 25/10/2026 | H13: GitHub Actions CI | O13: fragile item has nothing placed on top | P13: Fragile item + other items | Q13: Automated (Jest, CI) – be/src/modules/packing/solver/solver.spec.ts:79 | R13: Passed in CI (GitHub Actions run #258, commit 1a3101c, 25/10/2026)
A14: TC-F06-03 | B14: [Exception] Compute a plan for a group that is not picked yet | C14: 1. Request a plan for a group still in picking | D14: PACKING_WRONG_PLAN_STATUS; no plan created | E14: Group status picking | F14: Passed | G14: 25/10/2026 | H14: GitHub Actions CI | O14: group not fully picked → PACKING_WRONG_PLAN_STATUS | P14: Group id | Q14: Automated (Jest, CI) – be/src/modules/packing/packing-plan.service.spec.ts:294 | R14: Passed in CI (GitHub Actions run #258, commit 1a3101c, 25/10/2026)

Sheet F-07
A2: Feature | B2: F-07 Shipping with GHN | T2: Passed
A3: Test requirement | B3: Acceptance criteria of F-07 (Design Brief section 6): main flow, data / business rule, exception or permission | T3: Failed
A4: Number of TCs | B4: =COUNTA(A12:A1000)-COUNTIF(A12:A1000,"►*") | T4: Pending
A5: Testing Round | B5: Passed | C5: Failed | D5: Pending | E5: N/A | T5: N/A
A6: Round 1 | B6: =COUNTIF($F$12:$F$1000,B$5) | C6: =COUNTIF($F$12:$F$1000,C$5) | D6: =COUNTIF($F$12:$F$1000,D$5) | E6: =COUNTIF($F$12:$F$1000,E$5)
A7: Round 2 | B7: =COUNTIF($I$12:$I$1000,B$5) | C7: =COUNTIF($I$12:$I$1000,C$5) | D7: =COUNTIF($I$12:$I$1000,D$5) | E7: =COUNTIF($I$12:$I$1000,E$5)
A8: Round 3 | B8: =COUNTIF($L$12:$L$1000,B$5) | C8: =COUNTIF($L$12:$L$1000,C$5) | D8: =COUNTIF($L$12:$L$1000,D$5) | E8: =COUNTIF($L$12:$L$1000,E$5)
A10: Test Case ID | B10: Test Case Description | C10: Test Case Procedure | D10: Expected Results | E10: Pre-conditions | F10: Round 1 | G10: Test date | H10: Tester | I10: Round 2 | J10: Test date | K10: Tester | L10: Round 3 | M10: Test date | N10: Tester | O10: Note | P10: Test data | Q10: Run method / evidence | R10: Actual result
A11: ► F-07 Shipping with GHN
A12: TC-F07-01 | B12: [Main] Create a GHN shipment for a packed group | C12: 1. Open Shipping & Fulfillment 2. Choose a quote 3. Create shipment | D12: Shipment awaiting_pickup, each parcel has client_order_code, group → shipped, GHN codes stored | E12: Group packed | F12: Passed | G12: 25/10/2026 | H12: GitHub Actions CI | O12: shipment starts awaiting pickup, parcels have client_order_code, group → shipped | P12: GHN service, parcels | Q12: Automated (Jest, CI) – be/src/modules/shipments/shipments.service.carrier.spec.ts:124 | R12: Passed in CI (GitHub Actions run #258, commit 1a3101c, 25/10/2026)
A13: TC-F07-02 | B13: [Rule] Second failed delivery returns the shipment to the warehouse (no carrier API) | C13: 1. Record failed delivery 2. Record a second failed delivery | D13: Shipment moves automatically to returning_to_warehouse; two events recorded | E13: Shipment out for delivery, manual carrier | F13: Passed | G13: 25/10/2026 | H13: GitHub Actions CI | O13: 2nd failure → returning_to_warehouse automatically | P13: Reason: customer unreachable | Q13: Automated (Jest, CI) – be/src/modules/shipments/shipments.service.spec.ts:91 | R13: Passed in CI (GitHub Actions run #258, commit 1a3101c, 25/10/2026)
A14: TC-F07-03 | B14: [Exception] GHN rejects the address of a parcel | C14: 1. Create shipment with an invalid address | D14: Shipment kept, carrier_booking_error recorded, no CARRIER_BOOKED event | E14: Group packed | F14: Passed | G14: 25/10/2026 | H14: GitHub Actions CI | O14: carrier reports a wrong address → booking error recorded | P14: Wrong ward / address | Q14: Automated (Jest, CI) – be/src/modules/shipments/shipments.service.carrier.spec.ts:147 | R14: Passed in CI (GitHub Actions run #258, commit 1a3101c, 25/10/2026)

Sheet F-08
A2: Feature | B2: F-08 Returns and exchanges | T2: Passed
A3: Test requirement | B3: Acceptance criteria of F-08 (Design Brief section 6): main flow, data / business rule, exception or permission | T3: Failed
A4: Number of TCs | B4: =COUNTA(A12:A1000)-COUNTIF(A12:A1000,"►*") | T4: Pending
A5: Testing Round | B5: Passed | C5: Failed | D5: Pending | E5: N/A | T5: N/A
A6: Round 1 | B6: =COUNTIF($F$12:$F$1000,B$5) | C6: =COUNTIF($F$12:$F$1000,C$5) | D6: =COUNTIF($F$12:$F$1000,D$5) | E6: =COUNTIF($F$12:$F$1000,E$5)
A7: Round 2 | B7: =COUNTIF($I$12:$I$1000,B$5) | C7: =COUNTIF($I$12:$I$1000,C$5) | D7: =COUNTIF($I$12:$I$1000,D$5) | E7: =COUNTIF($I$12:$I$1000,E$5)
A8: Round 3 | B8: =COUNTIF($L$12:$L$1000,B$5) | C8: =COUNTIF($L$12:$L$1000,C$5) | D8: =COUNTIF($L$12:$L$1000,D$5) | E8: =COUNTIF($L$12:$L$1000,E$5)
A10: Test Case ID | B10: Test Case Description | C10: Test Case Procedure | D10: Expected Results | E10: Pre-conditions | F10: Round 1 | G10: Test date | H10: Tester | I10: Round 2 | J10: Test date | K10: Tester | L10: Round 3 | M10: Test date | N10: Tester | O10: Note | P10: Test data | Q10: Run method / evidence | R10: Actual result
A11: ► F-08 Returns and exchanges
A12: TC-F08-01 | B12: [Main] Customer requests a return on AURELLE | C12: 1. Open Order Detail of a delivered order 2. Press Request return 3. Submit | D12: Request created, customer timeline updated, OptiPack notified by webhook | E12: Order delivered ≤ 15 days ago | F12: Passed | G12: 25/10/2026 | H12: GitHub Actions CI | O12: valid request created and OptiPack notified | P12: Return & refund, 1 item | Q12: Automated (Jest, CI) – be/src/modules/storefront/storefront-returns.service.spec.ts:107 | R12: Passed in CI (GitHub Actions run #258, commit 1a3101c, 25/10/2026)
A13: TC-F08-02 | B13: [Rule] Return requested more than 15 days after delivery | C13: 1. Create a return for an order delivered 16 days ago | D13: 409 RMA_WINDOW_EXPIRED | E13: Delivered order | F13: Passed | G13: 25/10/2026 | H13: GitHub Actions CI | O13: more than 15 days since delivery → 409 RMA_WINDOW_EXPIRED | P13: Delivered at = today − 16 days | Q13: Automated (Jest, CI) – be/src/modules/shipments/returns.service.spec.ts:73 | R13: Passed in CI (GitHub Actions run #258, commit 1a3101c, 25/10/2026)
A14: TC-F08-03 | B14: [Permission] The creator of a return ticket approves it | C14: 1. User A creates a ticket 2. User A approves it | D14: 403 RMA_SELF_APPROVAL | E14: Ticket requested | F14: Passed | G14: 25/10/2026 | H14: GitHub Actions CI | O14: creator approves own ticket → 403 RMA_SELF_APPROVAL | P14: Same user | Q14: Automated (Jest, CI) – be/src/modules/shipments/returns.service.spec.ts:113 | R14: Passed in CI (GitHub Actions run #258, commit 1a3101c, 25/10/2026)

Sheet F-09
A2: Feature | B2: F-09 AURELLE web store and order tracking | T2: Passed
A3: Test requirement | B3: Acceptance criteria of F-09 (Design Brief section 6): main flow, data / business rule, exception or permission | T3: Failed
A4: Number of TCs | B4: =COUNTA(A12:A1000)-COUNTIF(A12:A1000,"►*") | T4: Pending
A5: Testing Round | B5: Passed | C5: Failed | D5: Pending | E5: N/A | T5: N/A
A6: Round 1 | B6: =COUNTIF($F$12:$F$1000,B$5) | C6: =COUNTIF($F$12:$F$1000,C$5) | D6: =COUNTIF($F$12:$F$1000,D$5) | E6: =COUNTIF($F$12:$F$1000,E$5)
A7: Round 2 | B7: =COUNTIF($I$12:$I$1000,B$5) | C7: =COUNTIF($I$12:$I$1000,C$5) | D7: =COUNTIF($I$12:$I$1000,D$5) | E7: =COUNTIF($I$12:$I$1000,E$5)
A8: Round 3 | B8: =COUNTIF($L$12:$L$1000,B$5) | C8: =COUNTIF($L$12:$L$1000,C$5) | D8: =COUNTIF($L$12:$L$1000,D$5) | E8: =COUNTIF($L$12:$L$1000,E$5)
A10: Test Case ID | B10: Test Case Description | C10: Test Case Procedure | D10: Expected Results | E10: Pre-conditions | F10: Round 1 | G10: Test date | H10: Tester | I10: Round 2 | J10: Test date | K10: Tester | L10: Round 3 | M10: Test date | N10: Tester | O10: Note | P10: Test data | Q10: Run method / evidence | R10: Actual result
A11: ► F-09 AURELLE web store and order tracking
A12: TC-F09-01 | B12: [Main] A newly placed order shows the 7-step progress bar | C12: 1. Place an order on AURELLE 2. Open Order Detail | D12: 7 steps shown, "Placed" is current with the order time | E12: Customer logged in | F12: Passed | G12: 25/10/2026 | H12: GitHub Actions CI | O12: new order: 7 steps, "Placed" current | P12: New order | Q12: Automated (Jest, CI) – be/src/modules/storefront/storefront-order-progress.spec.ts:7 | R12: Passed in CI (GitHub Actions run #258, commit 1a3101c, 25/10/2026)
A13: TC-F09-02 | B13: [Rule] An older status event never moves the order backwards | C13: 1. Send shipped 2. Send an older packed event | D13: History stored, order status not moved back | E13: Order already shipped | F13: Passed | G13: 25/10/2026 | H13: GitHub Actions CI | O13: older event stored but does not move the order back | P13: Out-of-order events | Q13: Automated (Jest, CI) – be/src/modules/storefront/aurelle-status-update.spec.ts:112 | R13: Passed in CI (GitHub Actions run #258, commit 1a3101c, 25/10/2026)
A14: TC-F09-03 | B14: [Exception] Failed delivery is shown with its reason | C14: 1. GHN reports failed delivery 2. Open Order Detail | D14: "Delivering to you" step shows an error with the latest reason | E14: Order out for delivery | F14: Passed | G14: 25/10/2026 | H14: GitHub Actions CI | O14: failed delivery: step shows error with reason | P14: Failure reason | Q14: Automated (Jest, CI) – be/src/modules/storefront/storefront-order-progress.spec.ts:44 | R14: Passed in CI (GitHub Actions run #258, commit 1a3101c, 25/10/2026)

Sheet F-10
A2: Feature | B2: F-10 Documents and labels | T2: Passed
A3: Test requirement | B3: Acceptance criteria of F-10 (Design Brief section 6): main flow, data / business rule, exception or permission | T3: Failed
A4: Number of TCs | B4: =COUNTA(A12:A1000)-COUNTIF(A12:A1000,"►*") | T4: Pending
A5: Testing Round | B5: Passed | C5: Failed | D5: Pending | E5: N/A | T5: N/A
A6: Round 1 | B6: =COUNTIF($F$12:$F$1000,B$5) | C6: =COUNTIF($F$12:$F$1000,C$5) | D6: =COUNTIF($F$12:$F$1000,D$5) | E6: =COUNTIF($F$12:$F$1000,E$5)
A7: Round 2 | B7: =COUNTIF($I$12:$I$1000,B$5) | C7: =COUNTIF($I$12:$I$1000,C$5) | D7: =COUNTIF($I$12:$I$1000,D$5) | E7: =COUNTIF($I$12:$I$1000,E$5)
A8: Round 3 | B8: =COUNTIF($L$12:$L$1000,B$5) | C8: =COUNTIF($L$12:$L$1000,C$5) | D8: =COUNTIF($L$12:$L$1000,D$5) | E8: =COUNTIF($L$12:$L$1000,E$5)
A10: Test Case ID | B10: Test Case Description | C10: Test Case Procedure | D10: Expected Results | E10: Pre-conditions | F10: Round 1 | G10: Test date | H10: Tester | I10: Round 2 | J10: Test date | K10: Tester | L10: Round 3 | M10: Test date | N10: Tester | O10: Note | P10: Test data | Q10: Run method / evidence | R10: Actual result
A11: ► F-10 Documents and labels
A12: TC-F10-01 | B12: [Main] Print the packing slip of a group | C12: 1. Open the group 2. Download packing slip | D12: Valid PDF, one page per order | E12: Group with orders | F12: Passed | G12: 25/10/2026 | H12: GitHub Actions CI | O12: packing slip: valid PDF, one page per order | P12: Group with 2 orders | Q12: Automated (Jest, CI) – be/src/modules/documents/pdf/document-renderers.spec.ts:24 | R12: Passed in CI (GitHub Actions run #258, commit 1a3101c, 25/10/2026)
A13: TC-F10-02 | B13: [Rule] GHN label: each parcel has its own carrier code and barcode | C13: 1. Create a shipment with 2 parcels 2. Download labels | D13: One page per parcel, each with its own carrier code / barcode | E13: Shipment booked with GHN | F13: Passed | G13: 25/10/2026 | H13: GitHub Actions CI | O13: GHN label: each parcel prints its own carrier code | P13: 2 parcels | Q13: Automated (Jest, CI) – be/src/modules/documents/pdf/document-renderers.spec.ts:76 | R13: Passed in CI (GitHub Actions run #258, commit 1a3101c, 25/10/2026)
A14: TC-F10-03 | B14: [Exception] Packing slip of an empty group | C14: 1. Download packing slip of a group without orders | D14: PDF with one notice page, no error | E14: Empty group | F14: Passed | G14: 25/10/2026 | H14: GitHub Actions CI | O14: packing slip: empty group still 1 notice page | P14: — | Q14: Automated (Jest, CI) – be/src/modules/documents/pdf/document-renderers.spec.ts:44 | R14: Passed in CI (GitHub Actions run #258, commit 1a3101c, 25/10/2026)

Sheet WF
A2: Feature | B2: Main workflows (end-to-end) | T2: Passed
A3: Test requirement | B3: One end-to-end main scenario per main workflow WF-01 … WF-06 (Design Brief A1 / A2) | T3: Failed
A4: Number of TCs | B4: =COUNTA(A12:A1000)-COUNTIF(A12:A1000,"►*") | T4: Pending
A5: Testing Round | B5: Passed | C5: Failed | D5: Pending | E5: N/A | T5: N/A
A6: Round 1 | B6: =COUNTIF($F$12:$F$1000,B$5) | C6: =COUNTIF($F$12:$F$1000,C$5) | D6: =COUNTIF($F$12:$F$1000,D$5) | E6: =COUNTIF($F$12:$F$1000,E$5)
A7: Round 2 | B7: =COUNTIF($I$12:$I$1000,B$5) | C7: =COUNTIF($I$12:$I$1000,C$5) | D7: =COUNTIF($I$12:$I$1000,D$5) | E7: =COUNTIF($I$12:$I$1000,E$5)
A8: Round 3 | B8: =COUNTIF($L$12:$L$1000,B$5) | C8: =COUNTIF($L$12:$L$1000,C$5) | D8: =COUNTIF($L$12:$L$1000,D$5) | E8: =COUNTIF($L$12:$L$1000,E$5)
A10: Test Case ID | B10: Test Case Description | C10: Test Case Procedure | D10: Expected Results | E10: Pre-conditions | F10: Round 1 | G10: Test date | H10: Tester | I10: Round 2 | J10: Test date | K10: Tester | L10: Round 3 | M10: Test date | N10: Tester | O10: Note | P10: Test data | Q10: Run method / evidence | R10: Actual result
A11: ► Main workflows (end-to-end)
A12: TC-WF01 | B12: [End-to-end] WF-01 Order Intake & Consolidation: main scenario end to end | C12: 1. Create a Lazada order 2. Wait for sync / press Sync (Admin) 3. Open Groups & Express | D12: Group created, stock reserved, picker assigned, status picking | E12: Lazada shop connected; SKUs mapped and in stock | F12: Pending | H12: Thuận | P12: Lazada order for 2 SKUs in stock (DS-01) | Q12: Manual on the staff portal / AURELLE website with seeded data | R12: Not executed yet – planned for the Verification stage (23/11–04/12/2026)
A13: TC-WF02 | B13: [End-to-end] WF-02 Picking: main scenario end to end | C13: 1. Log in as Warehouse Staff 2. Scan all items bin by bin 3. Press Complete picking | D13: Group picked; oldest lots consumed | E13: Group assigned to the picker | F13: Pending | H13: Phượng | P13: Group in picking with stock in bins (DS-03) | Q13: Manual on the staff portal / AURELLE website with seeded data | R13: Not executed yet – planned for the Verification stage (23/11–04/12/2026)
A14: TC-WF03 | B14: [End-to-end] WF-03 Packing: main scenario end to end | C14: 1. Log in as Packaging Staff 2. Approve the plan 3. Scan, seal and weigh every parcel | D14: Group packed; boxes and materials deducted | E14: Plan ready | F14: Pending | H14: Việt | P14: Picked group, SKU profiles confirmed (DS-05) | Q14: Manual on the staff portal / AURELLE website with seeded data | R14: Not executed yet – planned for the Verification stage (23/11–04/12/2026)
A15: TC-WF04 | B15: [End-to-end] WF-04 Shipping via GHN: main scenario end to end | C15: 1. Log in as Shipping Coordinator 2. Compare quotes, create shipment 3. Follow GHN status until delivered | D15: Shipment and group delivered; AURELLE customer sees every step | E15: Group packed; GHN staging configured | F15: Pending | H15: Thuận | P15: Packed group (DS-07) | Q15: Manual on the staff portal / AURELLE website with seeded data | R15: Not executed yet – planned for the Verification stage (23/11–04/12/2026)
A16: TC-WF05 | B16: [End-to-end] WF-05 Return / Exchange via AURELLE: main scenario end to end | C16: 1. Customer requests return on AURELLE 2. Store Owner approves 3. Warehouse Staff receives and inspects | D16: Ticket closed; refund recorded or replacement order created | E16: Order delivered ≤ 15 days | F16: Pending | H16: Thi | P16: Delivered AURELLE order within 15 days (DS-09) | Q16: Manual on the staff portal / AURELLE website with seeded data | R16: Not executed yet – planned for the Verification stage (23/11–04/12/2026)
A17: TC-WF06 | B17: [End-to-end] WF-06 Stock Receiving by Lot: main scenario end to end | C17: 1. Assign SKU to bin 2. Create stock receipt with lot code 3. Check bin stock and AURELLE stock | D17: Lot created; stock increased; shortage groups re-checked; stock pushed to AURELLE | E17: Warehouse structure created | F17: Pending | H17: Thi | P17: Warehouse with an empty bin (DS-11) | Q17: Manual on the staff portal / AURELLE website with seeded data | R17: Not executed yet – planned for the Verification stage (23/11–04/12/2026)

Sheet ST
A2: Feature | B2: Order Group state transitions | T2: Passed
A3: Test requirement | B3: Every allowed transition of the Order Group (be/src/modules/order-groups/enums/allowed-status-transitions.ts, 33 transitions); invalid jumps are rejected | T3: Failed
A4: Number of TCs | B4: =COUNTA(A12:A1000)-COUNTIF(A12:A1000,"►*") | T4: Pending
A5: Testing Round | B5: Passed | C5: Failed | D5: Pending | E5: N/A | T5: N/A
A6: Round 1 | B6: =COUNTIF($F$12:$F$1000,B$5) | C6: =COUNTIF($F$12:$F$1000,C$5) | D6: =COUNTIF($F$12:$F$1000,D$5) | E6: =COUNTIF($F$12:$F$1000,E$5)
A7: Round 2 | B7: =COUNTIF($I$12:$I$1000,B$5) | C7: =COUNTIF($I$12:$I$1000,C$5) | D7: =COUNTIF($I$12:$I$1000,D$5) | E7: =COUNTIF($I$12:$I$1000,E$5)
A8: Round 3 | B8: =COUNTIF($L$12:$L$1000,B$5) | C8: =COUNTIF($L$12:$L$1000,C$5) | D8: =COUNTIF($L$12:$L$1000,D$5) | E8: =COUNTIF($L$12:$L$1000,E$5)
A10: Test Case ID | B10: Test Case Description | C10: Test Case Procedure | D10: Expected Results | E10: Pre-conditions | F10: Round 1 | G10: Test date | H10: Tester | I10: Round 2 | J10: Test date | K10: Tester | L10: Round 3 | M10: Test date | N10: Tester | O10: Note | P10: Test data | Q10: Run method / evidence | R10: Actual result
A11: ► Order Group state transitions
A12: TC-ST01 | B12: [Transition] Order Group awaiting_packaging → picking | C12: 1. Group in awaiting_packaging 2. Picker assigned, picking starts | D12: Status becomes picking; invalid jumps from awaiting_packaging are rejected (ORD_GROUP state error) | E12: Order Group in status awaiting_packaging | F12: Passed | G12: 25/10/2026 | H12: GitHub Actions CI | O12: transition asserted (happy path) | P12: Picker assigned, picking starts | Q12: Automated (Jest, CI) – be/src/modules/order-groups/enums/allowed-status-transitions.spec.ts | R12: Passed in CI (GitHub Actions run #258, commit 1a3101c, 25/10/2026)
A13: TC-ST02 | B13: [Transition] Order Group awaiting_packaging → partial_needs_review | C13: 1. Group in awaiting_packaging 2. Missing item reported before picking starts | D13: Status becomes partial_needs_review; invalid jumps from awaiting_packaging are rejected (ORD_GROUP state error) | E13: Order Group in status awaiting_packaging | F13: Pending | H13: Phượng | P13: Missing item reported before picking starts | Q13: Manual: trigger the action on the portal and check the group status | R13: Not executed yet – planned for the Verification stage (23/11–04/12/2026)
A14: TC-ST03 | B14: [Transition] Order Group awaiting_packaging → canceled | C14: 1. Group in awaiting_packaging 2. All orders cancelled | D14: Status becomes canceled; invalid jumps from awaiting_packaging are rejected (ORD_GROUP state error) | E14: Order Group in status awaiting_packaging | F14: Passed | G14: 25/10/2026 | H14: GitHub Actions CI | O14: transition asserted (auto-cancel) | P14: All orders cancelled | Q14: Automated (Jest, CI) – be/src/modules/order-groups/enums/allowed-status-transitions.spec.ts | R14: Passed in CI (GitHub Actions run #258, commit 1a3101c, 25/10/2026)
A15: TC-ST04 | B15: [Transition] Order Group picking → picked | C15: 1. Group in picking 2. Complete picking | D15: Status becomes picked; invalid jumps from picking are rejected (ORD_GROUP state error) | E15: Order Group in status picking | F15: Passed | G15: 25/10/2026 | H15: GitHub Actions CI | O15: transition asserted (happy path) | P15: Complete picking | Q15: Automated (Jest, CI) – be/src/modules/order-groups/enums/allowed-status-transitions.spec.ts | R15: Passed in CI (GitHub Actions run #258, commit 1a3101c, 25/10/2026)
A16: TC-ST05 | B16: [Transition] Order Group picking → partial_needs_review | C16: 1. Group in picking 2. Report missing item | D16: Status becomes partial_needs_review; invalid jumps from picking are rejected (ORD_GROUP state error) | E16: Order Group in status picking | F16: Pending | H16: Phượng | P16: Report missing item | Q16: Manual: trigger the action on the portal and check the group status | R16: Not executed yet – planned for the Verification stage (23/11–04/12/2026)
A17: TC-ST06 | B17: [Transition] Order Group picking → canceled | C17: 1. Group in picking 2. All orders cancelled | D17: Status becomes canceled; invalid jumps from picking are rejected (ORD_GROUP state error) | E17: Order Group in status picking | F17: Passed | G17: 25/10/2026 | H17: GitHub Actions CI | O17: transition asserted (auto-cancel) | P17: All orders cancelled | Q17: Automated (Jest, CI) – be/src/modules/order-groups/enums/allowed-status-transitions.spec.ts | R17: Passed in CI (GitHub Actions run #258, commit 1a3101c, 25/10/2026)
A18: TC-ST07 | B18: [Transition] Order Group picked → pending_approval | C18: 1. Group in picked 2. Packing plan computed | D18: Status becomes pending_approval; invalid jumps from picked are rejected (ORD_GROUP state error) | E18: Order Group in status picked | F18: Passed | G18: 25/10/2026 | H18: GitHub Actions CI | O18: transition asserted (happy path) | P18: Packing plan computed | Q18: Automated (Jest, CI) – be/src/modules/order-groups/enums/allowed-status-transitions.spec.ts | R18: Passed in CI (GitHub Actions run #258, commit 1a3101c, 25/10/2026)
A19: TC-ST08 | B19: [Transition] Order Group picked → picking | C19: 1. Group in picked 2. Back to picking from packing | D19: Status becomes picking; invalid jumps from picked are rejected (ORD_GROUP state error) | E19: Order Group in status picked | F19: Pending | H19: Việt | P19: Back to picking from packing | Q19: Manual: trigger the action on the portal and check the group status | R19: Not executed yet – planned for the Verification stage (23/11–04/12/2026)
A20: TC-ST09 | B20: [Transition] Order Group picked → canceled | C20: 1. Group in picked 2. All orders cancelled | D20: Status becomes canceled; invalid jumps from picked are rejected (ORD_GROUP state error) | E20: Order Group in status picked | F20: Passed | G20: 25/10/2026 | H20: GitHub Actions CI | O20: transition asserted (auto-cancel) | P20: All orders cancelled | Q20: Automated (Jest, CI) – be/src/modules/order-groups/enums/allowed-status-transitions.spec.ts | R20: Passed in CI (GitHub Actions run #258, commit 1a3101c, 25/10/2026)
A21: TC-ST10 | B21: [Transition] Order Group partial_needs_review → picked | C21: 1. Group in partial_needs_review 2. Ship available items | D21: Status becomes picked; invalid jumps from partial_needs_review are rejected (ORD_GROUP state error) | E21: Order Group in status partial_needs_review | F21: Passed | G21: 25/10/2026 | H21: GitHub Actions CI | O21: transition asserted (partial → picked) | P21: Ship available items | Q21: Automated (Jest, CI) – be/src/modules/order-groups/enums/allowed-status-transitions.spec.ts | R21: Passed in CI (GitHub Actions run #258, commit 1a3101c, 25/10/2026)
A22: TC-ST11 | B22: [Transition] Order Group partial_needs_review → awaiting_packaging | C22: 1. Group in partial_needs_review 2. Re-queue until stock arrives | D22: Status becomes awaiting_packaging; invalid jumps from partial_needs_review are rejected (ORD_GROUP state error) | E22: Order Group in status partial_needs_review | F22: Passed | G22: 25/10/2026 | H22: GitHub Actions CI | O22: transition asserted (partial → awaiting) | P22: Re-queue until stock arrives | Q22: Automated (Jest, CI) – be/src/modules/order-groups/enums/allowed-status-transitions.spec.ts | R22: Passed in CI (GitHub Actions run #258, commit 1a3101c, 25/10/2026)
A23: TC-ST12 | B23: [Transition] Order Group partial_needs_review → picking | C23: 1. Group in partial_needs_review 2. Re-pick (new pick round) | D23: Status becomes picking; invalid jumps from partial_needs_review are rejected (ORD_GROUP state error) | E23: Order Group in status partial_needs_review | F23: Pending | H23: Phượng | P23: Re-pick (new pick round) | Q23: Manual: trigger the action on the portal and check the group status | R23: Not executed yet – planned for the Verification stage (23/11–04/12/2026)
A24: TC-ST13 | B24: [Transition] Order Group partial_needs_review → canceled | C24: 1. Group in partial_needs_review 2. All orders cancelled | D24: Status becomes canceled; invalid jumps from partial_needs_review are rejected (ORD_GROUP state error) | E24: Order Group in status partial_needs_review | F24: Passed | G24: 25/10/2026 | H24: GitHub Actions CI | O24: transition asserted (auto-cancel) | P24: All orders cancelled | Q24: Automated (Jest, CI) – be/src/modules/order-groups/enums/allowed-status-transitions.spec.ts | R24: Passed in CI (GitHub Actions run #258, commit 1a3101c, 25/10/2026)
A25: TC-ST14 | B25: [Transition] Order Group pending_approval → approved_for_packing | C25: 1. Group in pending_approval 2. Approve plan | D25: Status becomes approved_for_packing; invalid jumps from pending_approval are rejected (ORD_GROUP state error) | E25: Order Group in status pending_approval | F25: Passed | G25: 25/10/2026 | H25: GitHub Actions CI | O25: transition asserted (happy path) | P25: Approve plan | Q25: Automated (Jest, CI) – be/src/modules/order-groups/enums/allowed-status-transitions.spec.ts | R25: Passed in CI (GitHub Actions run #258, commit 1a3101c, 25/10/2026)
A26: TC-ST15 | B26: [Transition] Order Group pending_approval → picked | C26: 1. Group in pending_approval 2. Reject plan / recompute | D26: Status becomes picked; invalid jumps from pending_approval are rejected (ORD_GROUP state error) | E26: Order Group in status pending_approval | F26: Passed | G26: 25/10/2026 | H26: GitHub Actions CI | O26: transition asserted (reject plan) | P26: Reject plan / recompute | Q26: Automated (Jest, CI) – be/src/modules/order-groups/enums/allowed-status-transitions.spec.ts | R26: Passed in CI (GitHub Actions run #258, commit 1a3101c, 25/10/2026)
A27: TC-ST16 | B27: [Transition] Order Group pending_approval → canceled | C27: 1. Group in pending_approval 2. All orders cancelled | D27: Status becomes canceled; invalid jumps from pending_approval are rejected (ORD_GROUP state error) | E27: Order Group in status pending_approval | F27: Passed | G27: 25/10/2026 | H27: GitHub Actions CI | O27: transition asserted (auto-cancel) | P27: All orders cancelled | Q27: Automated (Jest, CI) – be/src/modules/order-groups/enums/allowed-status-transitions.spec.ts | R27: Passed in CI (GitHub Actions run #258, commit 1a3101c, 25/10/2026)
A28: TC-ST17 | B28: [Transition] Order Group approved_for_packing → packed | C28: 1. Group in approved_for_packing 2. Last parcel sealed | D28: Status becomes packed; invalid jumps from approved_for_packing are rejected (ORD_GROUP state error) | E28: Order Group in status approved_for_packing | F28: Passed | G28: 25/10/2026 | H28: GitHub Actions CI | O28: transition asserted (happy path) | P28: Last parcel sealed | Q28: Automated (Jest, CI) – be/src/modules/order-groups/enums/allowed-status-transitions.spec.ts | R28: Passed in CI (GitHub Actions run #258, commit 1a3101c, 25/10/2026)
A29: TC-ST18 | B29: [Transition] Order Group approved_for_packing → pending_approval | C29: 1. Group in approved_for_packing 2. Undo approval | D29: Status becomes pending_approval; invalid jumps from approved_for_packing are rejected (ORD_GROUP state error) | E29: Order Group in status approved_for_packing | F29: Passed | G29: 25/10/2026 | H29: GitHub Actions CI | O29: transition asserted (undo approve) | P29: Undo approval | Q29: Automated (Jest, CI) – be/src/modules/order-groups/enums/allowed-status-transitions.spec.ts | R29: Passed in CI (GitHub Actions run #258, commit 1a3101c, 25/10/2026)
A30: TC-ST19 | B30: [Transition] Order Group approved_for_packing → picked | C30: 1. Group in approved_for_packing 2. Recompute after approval | D30: Status becomes picked; invalid jumps from approved_for_packing are rejected (ORD_GROUP state error) | E30: Order Group in status approved_for_packing | F30: Pending | H30: Việt | P30: Recompute after approval | Q30: Manual: trigger the action on the portal and check the group status | R30: Not executed yet – planned for the Verification stage (23/11–04/12/2026)
A31: TC-ST20 | B31: [Transition] Order Group approved_for_packing → canceled | C31: 1. Group in approved_for_packing 2. All orders cancelled | D31: Status becomes canceled; invalid jumps from approved_for_packing are rejected (ORD_GROUP state error) | E31: Order Group in status approved_for_packing | F31: Passed | G31: 25/10/2026 | H31: GitHub Actions CI | O31: transition asserted (auto-cancel) | P31: All orders cancelled | Q31: Automated (Jest, CI) – be/src/modules/order-groups/enums/allowed-status-transitions.spec.ts | R31: Passed in CI (GitHub Actions run #258, commit 1a3101c, 25/10/2026)
A32: TC-ST21 | B32: [Transition] Order Group approved_for_packing → picking | C32: 1. Group in approved_for_packing 2. Damaged / missing item while packing, back to picking | D32: Status becomes picking; invalid jumps from approved_for_packing are rejected (ORD_GROUP state error) | E32: Order Group in status approved_for_packing | F32: Passed | G32: 25/10/2026 | H32: GitHub Actions CI | O32: transition asserted (back to picking) | P32: Damaged / missing item while packing, back to picking | Q32: Automated (Jest, CI) – be/src/modules/order-groups/enums/allowed-status-transitions.spec.ts | R32: Passed in CI (GitHub Actions run #258, commit 1a3101c, 25/10/2026)
A33: TC-ST22 | B33: [Transition] Order Group packed → shipped | C33: 1. Group in packed 2. Shipment created | D33: Status becomes shipped; invalid jumps from packed are rejected (ORD_GROUP state error) | E33: Order Group in status packed | F33: Passed | G33: 25/10/2026 | H33: GitHub Actions CI | O33: transition asserted (happy path) | P33: Shipment created | Q33: Automated (Jest, CI) – be/src/modules/order-groups/enums/allowed-status-transitions.spec.ts | R33: Passed in CI (GitHub Actions run #258, commit 1a3101c, 25/10/2026)
A34: TC-ST23 | B34: [Transition] Order Group packed → canceled | C34: 1. Group in packed 2. Orders cancelled after packing (unpack parcels) | D34: Status becomes canceled; invalid jumps from packed are rejected (ORD_GROUP state error) | E34: Order Group in status packed | F34: Passed | G34: 25/10/2026 | H34: GitHub Actions CI | O34: transition asserted (packed → canceled) | P34: Orders cancelled after packing (unpack parcels) | Q34: Automated (Jest, CI) – be/src/modules/order-groups/enums/allowed-status-transitions.spec.ts | R34: Passed in CI (GitHub Actions run #258, commit 1a3101c, 25/10/2026)
A35: TC-ST24 | B35: [Transition] Order Group packed → approved_for_packing | C35: 1. Group in packed 2. Reopen / repack a parcel | D35: Status becomes approved_for_packing; invalid jumps from packed are rejected (ORD_GROUP state error) | E35: Order Group in status packed | F35: Pending | H35: Thuận | P35: Reopen / repack a parcel | Q35: Manual: trigger the action on the portal and check the group status | R35: Not executed yet – planned for the Verification stage (23/11–04/12/2026)
A36: TC-ST25 | B36: [Transition] Order Group shipped → delivered | C36: 1. Group in shipped 2. Carrier delivered | D36: Status becomes delivered; invalid jumps from shipped are rejected (ORD_GROUP state error) | E36: Order Group in status shipped | F36: Passed | G36: 25/10/2026 | H36: GitHub Actions CI | O36: transition asserted (happy path) | P36: Carrier delivered | Q36: Automated (Jest, CI) – be/src/modules/order-groups/enums/allowed-status-transitions.spec.ts | R36: Passed in CI (GitHub Actions run #258, commit 1a3101c, 25/10/2026)
A37: TC-ST26 | B37: [Transition] Order Group shipped → returned | C37: 1. Group in shipped 2. Returned to warehouse after failed delivery | D37: Status becomes returned; invalid jumps from shipped are rejected (ORD_GROUP state error) | E37: Order Group in status shipped | F37: Passed | G37: 25/10/2026 | H37: GitHub Actions CI | O37: transition asserted (shipped → returned) | P37: Returned to warehouse after failed delivery | Q37: Automated (Jest, CI) – be/src/modules/order-groups/enums/allowed-status-transitions.spec.ts | R37: Passed in CI (GitHub Actions run #258, commit 1a3101c, 25/10/2026)
A38: TC-ST27 | B38: [Transition] Order Group shipped → packed | C38: 1. Group in shipped 2. GHN order cancelled before pickup | D38: Status becomes packed; invalid jumps from shipped are rejected (ORD_GROUP state error) | E38: Order Group in status shipped | F38: Passed | G38: 25/10/2026 | H38: GitHub Actions CI | O38: transition asserted (shipped → packed) | P38: GHN order cancelled before pickup | Q38: Automated (Jest, CI) – be/src/modules/order-groups/enums/allowed-status-transitions.spec.ts | R38: Passed in CI (GitHub Actions run #258, commit 1a3101c, 25/10/2026)
A39: TC-ST28 | B39: [Transition] Order Group delivered → returning | C39: 1. Group in delivered 2. Full return ticket created | D39: Status becomes returning; invalid jumps from delivered are rejected (ORD_GROUP state error) | E39: Order Group in status delivered | F39: Passed | G39: 25/10/2026 | H39: GitHub Actions CI | O39: transition asserted (returning) | P39: Full return ticket created | Q39: Automated (Jest, CI) – be/src/modules/order-groups/enums/allowed-status-transitions.spec.ts | R39: Passed in CI (GitHub Actions run #258, commit 1a3101c, 25/10/2026)
A40: TC-ST29 | B40: [Transition] Order Group delivered → returned | C40: 1. Group in delivered 2. Return received after delivery | D40: Status becomes returned; invalid jumps from delivered are rejected (ORD_GROUP state error) | E40: Order Group in status delivered | F40: Passed | G40: 25/10/2026 | H40: GitHub Actions CI | O40: transition asserted (delivered → returned) | P40: Return received after delivery | Q40: Automated (Jest, CI) – be/src/modules/order-groups/enums/allowed-status-transitions.spec.ts | R40: Passed in CI (GitHub Actions run #258, commit 1a3101c, 25/10/2026)
A41: TC-ST30 | B41: [Transition] Order Group returning → returned | C41: 1. Group in returning 2. Returned goods received | D41: Status becomes returned; invalid jumps from returning are rejected (ORD_GROUP state error) | E41: Order Group in status returning | F41: Passed | G41: 25/10/2026 | H41: GitHub Actions CI | O41: transition asserted (next statuses of returning) | P41: Returned goods received | Q41: Automated (Jest, CI) – be/src/modules/order-groups/enums/allowed-status-transitions.spec.ts | R41: Passed in CI (GitHub Actions run #258, commit 1a3101c, 25/10/2026)
A42: TC-ST31 | B42: [Transition] Order Group returning → delivered | C42: 1. Group in returning 2. Return ticket rejected / cancelled | D42: Status becomes delivered; invalid jumps from returning are rejected (ORD_GROUP state error) | E42: Order Group in status returning | F42: Passed | G42: 25/10/2026 | H42: GitHub Actions CI | O42: transition asserted (next statuses of returning) | P42: Return ticket rejected / cancelled | Q42: Automated (Jest, CI) – be/src/modules/order-groups/enums/allowed-status-transitions.spec.ts | R42: Passed in CI (GitHub Actions run #258, commit 1a3101c, 25/10/2026)
...

Sheet NFR
A2: Feature | B2: Non-functional requirements | T2: Passed
A3: Test requirement | B3: Each agreed NFR measured with its metric and threshold (Design Brief section 7) | T3: Failed
A4: Number of TCs | B4: =COUNTA(A12:A1000)-COUNTIF(A12:A1000,"►*") | T4: Pending
A5: Testing Round | B5: Passed | C5: Failed | D5: Pending | E5: N/A | T5: N/A
A6: Round 1 | B6: =COUNTIF($F$12:$F$1000,B$5) | C6: =COUNTIF($F$12:$F$1000,C$5) | D6: =COUNTIF($F$12:$F$1000,D$5) | E6: =COUNTIF($F$12:$F$1000,E$5)
A7: Round 2 | B7: =COUNTIF($I$12:$I$1000,B$5) | C7: =COUNTIF($I$12:$I$1000,C$5) | D7: =COUNTIF($I$12:$I$1000,D$5) | E7: =COUNTIF($I$12:$I$1000,E$5)
A8: Round 3 | B8: =COUNTIF($L$12:$L$1000,B$5) | C8: =COUNTIF($L$12:$L$1000,C$5) | D8: =COUNTIF($L$12:$L$1000,D$5) | E8: =COUNTIF($L$12:$L$1000,E$5)
